Workbook

Sheet Document Register
A1: Master Document Register
A3: Document Number | B3: Document Title | C3: Project Name | D3: Client Name | E3: Discipline | F3: Revision No. | G3: Submission Date | H3: Approval Date | I3: Status | J3: Responsible Engineer | K3: Remarks | L3: Aging (Days)
A4: PRJ01-CIV-0001 | B4: Foundation Drawing | C4: Metro Project | D4: ABC Ltd | E4: Civil | F4: Rev-00 | G4: 46023 | H4: 46026 | I4: Approved | J4: Ahmed Khan | K4: Approved | L4: =IF(G4="","",TODAY()-G4) -> 221
A5: PRJ02-MEC-0002 | B5: HVAC Layout | C5: Airport Project | D5: XYZ Ltd | E5: Mechanical | F5: Rev-01 | G5: 46025 | I5: Submitted | J5: Ali Raza | K5: Pending | L5: =IF(G5="","",TODAY()-G5) -> 219
A6: PRJ03-ELE-0003 | B6: Cable Schedule | C6: Hospital Project | D6: GHI Ltd | E6: Electrical | F6: Rev-02 | G6: 46027 | I6: Under Review | J6: John Mathew | K6: Review | L6: =IF(G6="","",TODAY()-G6) -> 217
A7: PRJ04-ELV-0004 | B7: CCTV Layout | C7: Refinery Upgrade | D7: OilCorp | E7: ELV | F7: Rev-03 | G7: 46029 | I7: Draft | J7: Salman Ali | K7: Draft | L7: =IF(G7="","",TODAY()-G7) -> 215
A8: PRJ05-HSE-0005 | B8: Risk Assessment | C8: IT Park | D8: PQR Ltd | E8: HSE | F8: Rev-00 | G8: 46031 | I8: Rejected | J8: Imran Ahmed | K8: Resubmit | L8: =IF(G8="","",TODAY()-G8) -> 213
A9: PRJ06-QA/-0006 | B9: ITP Document | C9: Data Center | D9: NABCO | E9: QA/QC | F9: Rev-01 | G9: 46033 | H9: 46036 | I9: Approved | J9: Hassan Khan | K9: Approved | L9: =IF(G9="","",TODAY()-G9) -> 211
A10: PRJ07-CIV-0007 | B10: Foundation Drawing | C10: Mall Project | D10: Delta EPC | E10: Civil | F10: Rev-02 | G10: 46035 | I10: Submitted | J10: Ahmed Khan | K10: Pending | L10: =IF(G10="","",TODAY()-G10) -> 209
A11: PRJ08-MEC-0008 | B11: HVAC Layout | C11: Bridge Project | D11: Prime Infra | E11: Mechanical | F11: Rev-03 | G11: 46037 | I11: Under Review | J11: Ali Raza | K11: Review | L11: =IF(G11="","",TODAY()-G11) -> 207
A12: PRJ09-ELE-0009 | B12: Cable Schedule | C12: Residential Tower | D12: SkyBuild | E12: Electrical | F12: Rev-00 | G12: 46039 | I12: Draft | J12: John Mathew | K12: Draft | L12: =IF(G12="","",TODAY()-G12) -> 205
A13: PRJ10-ELV-0010 | B13: CCTV Layout | C13: Industrial Plant | D13: Vision Tech | E13: ELV | F13: Rev-01 | G13: 46041 | I13: Rejected | J13: Salman Ali | K13: Resubmit | L13: =IF(G13="","",TODAY()-G13) -> 203
A14: PRJ01-HSE-0011 | B14: Risk Assessment | C14: Metro Project | D14: ABC Ltd | E14: HSE | F14: Rev-02 | G14: 46043 | H14: 46046 | I14: Approved | J14: Imran Ahmed | K14: Approved | L14: =IF(G14="","",TODAY()-G14) -> 201
A15: PRJ02-QA/-0012 | B15: ITP Document | C15: Airport Project | D15: XYZ Ltd | E15: QA/QC | F15: Rev-03 | G15: 46045 | I15: Submitted | J15: Hassan Khan | K15: Pending | L15: =IF(G15="","",TODAY()-G15) -> 199
A16: PRJ03-CIV-0013 | B16: Foundation Drawing | C16: Hospital Project | D16: GHI Ltd | E16: Civil | F16: Rev-00 | G16: 46047 | I16: Under Review | J16: Ahmed Khan | K16: Review | L16: =IF(G16="","",TODAY()-G16) -> 197
A17: PRJ04-MEC-0014 | B17: HVAC Layout | C17: Refinery Upgrade | D17: OilCorp | E17: Mechanical | F17: Rev-01 | G17: 46049 | I17: Draft | J17: Ali Raza | K17: Draft | L17: =IF(G17="","",TODAY()-G17) -> 195
A18: PRJ05-ELE-0015 | B18: Cable Schedule | C18: IT Park | D18: PQR Ltd | E18: Electrical | F18: Rev-02 | G18: 46051 | I18: Rejected | J18: John Mathew | K18: Resubmit | L18: =IF(G18="","",TODAY()-G18) -> 193
A19: PRJ06-ELV-0016 | B19: CCTV Layout | C19: Data Center | D19: NABCO | E19: ELV | F19: Rev-03 | G19: 46053 | H19: 46056 | I19: Approved | J19: Salman Ali | K19: Approved | L19: =IF(G19="","",TODAY()-G19) -> 191
A20: PRJ07-HSE-0017 | B20: Risk Assessment | C20: Mall Project | D20: Delta EPC | E20: HSE | F20: Rev-00 | G20: 46055 | I20: Submitted | J20: Imran Ahmed | K20: Pending | L20: =IF(G20="","",TODAY()-G20) -> 189
A21: PRJ08-QA/-0018 | B21: ITP Document | C21: Bridge Project | D21: Prime Infra | E21: QA/QC | F21: Rev-01 | G21: 46057 | I21: Under Review | J21: Hassan Khan | K21: Review | L21: =IF(G21="","",TODAY()-G21) -> 187
A22: PRJ09-CIV-0019 | B22: Foundation Drawing | C22: Residential Tower | D22: SkyBuild | E22: Civil | F22: Rev-02 | G22: 46059 | I22: Draft | J22: Ahmed Khan | K22: Draft | L22: =IF(G22="","",TODAY()-G22) -> 185
A23: PRJ10-MEC-0020 | B23: HVAC Layout | C23: Industrial Plant | D23: Vision Tech | E23: Mechanical | F23: Rev-03 | G23: 46061 | I23: Rejected | J23: Ali Raza | K23: Resubmit | L23: =IF(G23="","",TODAY()-G23) -> 183
A24: PRJ01-ELE-0021 | B24: Cable Schedule | C24: Metro Project | D24: ABC Ltd | E24: Electrical | F24: Rev-00 | G24: 46063 | H24: 46066 | I24: Approved | J24: John Mathew | K24: Approved | L24: =IF(G24="","",TODAY()-G24) -> 181
A25: PRJ02-ELV-0022 | B25: CCTV Layout | C25: Airport Project | D25: XYZ Ltd | E25: ELV | F25: Rev-01 | G25: 46065 | I25: Submitted | J25: Salman Ali | K25: Pending | L25: =IF(G25="","",TODAY()-G25) -> 179
A26: PRJ03-HSE-0023 | B26: Risk Assessment | C26: Hospital Project | D26: GHI Ltd | E26: HSE | F26: Rev-02 | G26: 46067 | I26: Under Review | J26: Imran Ahmed | K26: Review | L26: =IF(G26="","",TODAY()-G26) -> 177
A27: PRJ04-QA/-0024 | B27: ITP Document | C27: Refinery Upgrade | D27: OilCorp | E27: QA/QC | F27: Rev-03 | G27: 46069 | I27: Draft | J27: Hassan Khan | K27: Draft | L27: =IF(G27="","",TODAY()-G27) -> 175
A28: PRJ05-CIV-0025 | B28: Foundation Drawing | C28: IT Park | D28: PQR Ltd | E28: Civil | F28: Rev-00 | G28: 46071 | I28: Rejected | J28: Ahmed Khan | K28: Resubmit | L28: =IF(G28="","",TODAY()-G28) -> 173
A29: PRJ06-MEC-0026 | B29: HVAC Layout | C29: Data Center | D29: NABCO | E29: Mechanical | F29: Rev-01 | G29: 46073 | H29: 46076 | I29: Approved | J29: Ali Raza | K29: Approved | L29: =IF(G29="","",TODAY()-G29) -> 171
A30: PRJ07-ELE-0027 | B30: Cable Schedule | C30: Mall Project | D30: Delta EPC | E30: Electrical | F30: Rev-02 | G30: 46075 | I30: Submitted | J30: John Mathew | K30: Pending | L30: =IF(G30="","",TODAY()-G30) -> 169
A31: PRJ08-ELV-0028 | B31: CCTV Layout | C31: Bridge Project | D31: Prime Infra | E31: ELV | F31: Rev-03 | G31: 46077 | I31: Under Review | J31: Salman Ali | K31: Review | L31: =IF(G31="","",TODAY()-G31) -> 167
A32: PRJ09-HSE-0029 | B32: Risk Assessment | C32: Residential Tower | D32: SkyBuild | E32: HSE | F32: Rev-00 | G32: 46079 | I32: Draft | J32: Imran Ahmed | K32: Draft | L32: =IF(G32="","",TODAY()-G32) -> 165
A33: PRJ10-QA/-0030 | B33: ITP Document | C33: Industrial Plant | D33: Vision Tech | E33: QA/QC | F33: Rev-01 | G33: 46081 | I33: Rejected | J33: Hassan Khan | K33: Resubmit | L33: =IF(G33="","",TODAY()-G33) -> 163
A34: PRJ01-CIV-0031 | B34: Foundation Drawing | C34: Metro Project | D34: ABC Ltd | E34: Civil | F34: Rev-02 | G34: 46083 | H34: 46086 | I34: Approved | J34: Ahmed Khan | K34: Approved | L34: =IF(G34="","",TODAY()-G34) -> 161
A35: PRJ02-MEC-0032 | B35: HVAC Layout | C35: Airport Project | D35: XYZ Ltd | E35: Mechanical | F35: Rev-03 | G35: 46085 | I35: Submitted | J35: Ali Raza | K35: Pending | L35: =IF(G35="","",TODAY()-G35) -> 159
A36: PRJ03-ELE-0033 | B36: Cable Schedule | C36: Hospital Project | D36: GHI Ltd | E36: Electrical | F36: Rev-00 | G36: 46087 | I36: Under Review | J36: John Mathew | K36: Review | L36: =IF(G36="","",TODAY()-G36) -> 157
A37: PRJ04-ELV-0034 | B37: CCTV Layout | C37: Refinery Upgrade | D37: OilCorp | E37: ELV | F37: Rev-01 | G37: 46089 | I37: Draft | J37: Salman Ali | K37: Draft | L37: =IF(G37="","",TODAY()-G37) -> 155
A38: PRJ05-HSE-0035 | B38: Risk Assessment | C38: IT Park | D38: PQR Ltd | E38: HSE | F38: Rev-02 | G38: 46091 | I38: Rejected | J38: Imran Ahmed | K38: Resubmit | L38: =IF(G38="","",TODAY()-G38) -> 153
A39: PRJ06-QA/-0036 | B39: ITP Document | C39: Data Center | D39: NABCO | E39: QA/QC | F39: Rev-03 | G39: 46093 | H39: 46096 | I39: Approved | J39: Hassan Khan | K39: Approved | L39: =IF(G39="","",TODAY()-G39) -> 151
A40: PRJ07-CIV-0037 | B40: Foundation Drawing | C40: Mall Project | D40: Delta EPC | E40: Civil | F40: Rev-00 | G40: 46095 | I40: Submitted | J40: Ahmed Khan | K40: Pending | L40: =IF(G40="","",TODAY()-G40) -> 149
A41: PRJ08-MEC-0038 | B41: HVAC Layout | C41: Bridge Project | D41: Prime Infra | E41: Mechanical | F41: Rev-01 | G41: 46097 | I41: Under Review | J41: Ali Raza | K41: Review | L41: =IF(G41="","",TODAY()-G41) -> 147
...

Sheet Data-detail
D1: Project Name | E1: Client Name | F1: Discipline | G1: Responsible Engineer
D2: Metro Project | E2: ABC Ltd | F2: Civil | G2: Ahmed Khan
D3: Airport Project | E3: XYZ Ltd | F3: Mechanical | G3: Ali Raza
D4: Hospital Project | E4: GHI Ltd | F4: Electrical | G4: John Mathew
D5: IT Park | E5: PQR Ltd | F5: ELV | G5: Salman Ali
D6: Mall Project | E6: DEF Ltd | F6: HSE | G6: Imran Ahmed
D7: Refinery | E7: OilCorp | F7: QA/QC | G7: Hassan Khan
D8: Bridge Project | E8: LMN Ltd | F8: Civil | G8: Ahmed Khan

Sheet KPI Matrix
D3: KPI | E3: Formula | F3: Target
D4: Total Documents | E4: =COUNTA('Document Register'!A2:A103) -> 101 | F4: 200
D5: Approved | E5: =COUNTIF('Document Register'!I2:I103,"Approved") -> 20 | F5: ≥90%
D6: Submitted | E6: =COUNTIF('Document Register'!I2:I103,"Submitted") -> 20 | F6: -
D7: Under Review | E7: =COUNTIF('Document Register'!I2:I103,"Under Review") -> 20 | F7: -
D8: Rejected | E8: =COUNTIF('Document Register'!I2:I103,"Rejected") -> 20 | F8: <5%
D9: Overdue | E9: =COUNTIFS('Document Register'!L2:L103,">30",'Document Register'!I2:I103,"<>Approved") -> 76 | F9: <5%
D10: On-Time Submission % | E10: =(COUNTIFS('Document Register'!L2:L103,"<=30")/COUNTA('Document Register'!A2:A103))*100 -> 3.960396 | F10: ≥95%
D11: Approval Success Rate | E11: =(COUNTIF('Document Register'!I2:I103,"Approved")/COUNTA('Document Register'!A2:A103))*100 -> 19.80198 | F11: ≥90%
D12: Document Accuracy % | E12: =((COUNTA('Document Register'!A2:A103)-COUNTIF('Document Register'!K2:K103,"*Error*"))/COUNTA('Document Register'!A2:A103))*100 -> 100 | F12: ≥99%

Sheet KRA
D1: KRA | E1: Objective | F1: Responsibilities | G1: Measurement
D2: Document Control | E2: Maintain project documents | F2: Register, revise, archive | G2: 99% Accuracy
D3: Submission Management | E3: Timely submissions | F3: Submit & track approvals | G3: ≥95% On-Time
D4: Client Coordination | E4: Client communication | F4: Follow up comments | G4: ≥90% Approval
D5: Reporting & Dashboard | E5: Prepare reports | F5: Excel & Power BI updates | G5: 100% Reports
D6: QA/QC Documentation | E6: Maintain QA records | F6: ITP, Method Statement | G6: Zero Missing Docs
D7: Records Management | E7: Archive records | F7: Store & retrieve documents | G7: 100% Retrieval
